<?xml version="1.0" ?>
<!-- =================================================================================== -->
<!-- |    This document was autogenerated by xacro from kit_c_base.xacro               | -->
<!-- |    EDITING THIS FILE BY HAND IS NOT RECOMMENDED                                 | -->
<!-- =================================================================================== -->
<robot name="quad">
  <link name="base_link"/>
  <joint name="base_joint" type="fixed">
    <origin rpy="0 0 0" xyz="0 0 0"/>
    <parent link="base_link"/>
    <child link="base_link_inertia"/>
  </joint>
  <link name="base_link_inertia">
    <inertial>
      <mass value="1.4"/>
      <!-- [kg] -->
      <origin xyz="0 0 0"/>
      <inertia ixx="0.05" ixy="0.0" ixz="0.0" iyy="0.05" iyz="0.0" izz="0.24"/>
    </inertial>
    <visual>
      <origin rpy="0 0 0" xyz="0 0 0"/>
      <geometry>
        <mesh filename="package://acl_sim/meshes/wilSelby/hummingbird.dae" scale="1 1 1"/>
        <!-- <box size="${body_width} ${body_width} ${body_height}"/> -->
        <!-- [m] [m] [m] -->
      </geometry>
    </visual>
    <collision>
      <origin rpy="0 0 0" xyz="0 0 0"/>
      <geometry>
        <box size="0.3 0.3 0.17"/>
        <!-- [m] [m] [m] -->
      </geometry>
    </collision>
  </link>
  <!-- attach multirotor_base_plugin to the base_link -->
  <gazebo>
    <plugin filename="librotors_gazebo_multirotor_base_plugin.so" name="rosbag">
      <robotNamespace>quad</robotNamespace>
      <linkName>base_link</linkName>
      <rotorVelocitySlowdownSim>10</rotorVelocitySlowdownSim>
    </plugin>
  </gazebo>
  <gazebo reference="base_link">
    <material>Gazebo/DarkGrey</material>
  </gazebo>
  <joint name="rotor_0_joint" type="continuous">
    <origin rpy="0 0 0" xyz="0.17 0 0.01"/>
    <axis xyz="0 0 1"/>
    <!-- TODO(ff): not currently set because it's not yet supported -->
    <!-- <limit effort="2000" velocity="${max_rot_velocity}" /> -->
    <parent link="base_link"/>
    <child link="rotor_0"/>
  </joint>
  <!-- TODO(ff): not currently set because it's not yet supported -->
  <!-- <gazebo reference="rotor_${motor_number}_joint"> <axis> <xyz>0 0 1</xyz>
      <limit> <velocity> ${max_rot_velocity} </velocity> </limit> </axis> </gazebo> -->
  <link name="rotor_0">
    <inertial>
      <mass value="0.005"/>
      <!-- [kg] -->
      <inertia ixx="9.75e-07" ixy="0.0" ixz="0.0" iyy="0.00032670416666666667" iyz="0.0" izz="0.0003276041666666667"/>
    </inertial>
    <visual>
      <geometry>
        <!-- <cylinder length="0.005" radius="${radius_rotor}"/> -->
        <!-- [m] -->
        <!-- <mesh filename="package://rotors_description/meshes/propeller_${direction}.dae" -->
        <mesh filename="package://acl_sim/meshes/wilSelby/propeller_ccw.dae" scale=".12 .12 .12"/>
        <!-- <box size="${2*radius_rotor} 0.01 0.005"/> -->
      </geometry>
    </visual>
    <collision>
      <geometry>
        <cylinder length="0.005" radius="0.14"/>
        <!-- [m] -->
      </geometry>
    </collision>
  </link>
  <gazebo>
    <plugin filename="librotors_gazebo_motor_model.so" name="front_motor_model">
      <robotNamespace>quad</robotNamespace>
      <jointName>rotor_0_joint</jointName>
      <linkName>rotor_0</linkName>
      <turningDirection>ccw</turningDirection>
      <timeConstantUp>0.15</timeConstantUp>
      <timeConstantDown>0.15</timeConstantDown>
      <maxRotVelocity>770</maxRotVelocity>
      <motorConstant>2.39e-05</motorConstant>
      <momentConstant>0.016</momentConstant>
      <commandSubTopic>gazebo/command/motor_speed</commandSubTopic>
      <motorNumber>0</motorNumber>
      <rotorDragCoefficient>1.3858e-06</rotorDragCoefficient>
      <rollingMomentCoefficient>1e-06</rollingMomentCoefficient>
      <motorSpeedPubTopic>motor_speed/0</motorSpeedPubTopic>
      <rotorVelocitySlowdownSim>10</rotorVelocitySlowdownSim>
    </plugin>
  </gazebo>
  <gazebo reference="rotor_0">
    <material>Gazebo/Blue</material>
  </gazebo>
  <joint name="rotor_1_joint" type="continuous">
    <origin rpy="0 0 0" xyz="0 -0.17 0.01"/>
    <axis xyz="0 0 1"/>
    <!-- TODO(ff): not currently set because it's not yet supported -->
    <!-- <limit effort="2000" velocity="${max_rot_velocity}" /> -->
    <parent link="base_link"/>
    <child link="rotor_1"/>
  </joint>
  <!-- TODO(ff): not currently set because it's not yet supported -->
  <!-- <gazebo reference="rotor_${motor_number}_joint"> <axis> <xyz>0 0 1</xyz>
      <limit> <velocity> ${max_rot_velocity} </velocity> </limit> </axis> </gazebo> -->
  <link name="rotor_1">
    <inertial>
      <mass value="0.005"/>
      <!-- [kg] -->
      <inertia ixx="9.75e-07" ixy="0.0" ixz="0.0" iyy="0.00032670416666666667" iyz="0.0" izz="0.0003276041666666667"/>
    </inertial>
    <visual>
      <geometry>
        <!-- <cylinder length="0.005" radius="${radius_rotor}"/> -->
        <!-- [m] -->
        <!-- <mesh filename="package://rotors_description/meshes/propeller_${direction}.dae" -->
        <mesh filename="package://acl_sim/meshes/wilSelby/propeller_cw.dae" scale=".12 .12 .12"/>
        <!-- <box size="${2*radius_rotor} 0.01 0.005"/> -->
      </geometry>
    </visual>
    <collision>
      <geometry>
        <cylinder length="0.005" radius="0.14"/>
        <!-- [m] -->
      </geometry>
    </collision>
  </link>
  <gazebo>
    <plugin filename="librotors_gazebo_motor_model.so" name="right_motor_model">
      <robotNamespace>quad</robotNamespace>
      <jointName>rotor_1_joint</jointName>
      <linkName>rotor_1</linkName>
      <turningDirection>cw</turningDirection>
      <timeConstantUp>0.15</timeConstantUp>
      <timeConstantDown>0.15</timeConstantDown>
      <maxRotVelocity>770</maxRotVelocity>
      <motorConstant>2.39e-05</motorConstant>
      <momentConstant>0.016</momentConstant>
      <commandSubTopic>gazebo/command/motor_speed</commandSubTopic>
      <motorNumber>1</motorNumber>
      <rotorDragCoefficient>1.3858e-06</rotorDragCoefficient>
      <rollingMomentCoefficient>1e-06</rollingMomentCoefficient>
      <motorSpeedPubTopic>motor_speed/1</motorSpeedPubTopic>
      <rotorVelocitySlowdownSim>10</rotorVelocitySlowdownSim>
    </plugin>
  </gazebo>
  <gazebo reference="rotor_1">
    <material>Gazebo/Grey</material>
  </gazebo>
  <joint name="rotor_2_joint" type="continuous">
    <origin rpy="0 0 0" xyz="-0.17 0 0.01"/>
    <axis xyz="0 0 1"/>
    <!-- TODO(ff): not currently set because it's not yet supported -->
    <!-- <limit effort="2000" velocity="${max_rot_velocity}" /> -->
    <parent link="base_link"/>
    <child link="rotor_2"/>
  </joint>
  <!-- TODO(ff): not currently set because it's not yet supported -->
  <!-- <gazebo reference="rotor_${motor_number}_joint"> <axis> <xyz>0 0 1</xyz>
      <limit> <velocity> ${max_rot_velocity} </velocity> </limit> </axis> </gazebo> -->
  <link name="rotor_2">
    <inertial>
      <mass value="0.005"/>
      <!-- [kg] -->
      <inertia ixx="9.75e-07" ixy="0.0" ixz="0.0" iyy="0.00032670416666666667" iyz="0.0" izz="0.0003276041666666667"/>
    </inertial>
    <visual>
      <geometry>
        <!-- <cylinder length="0.005" radius="${radius_rotor}"/> -->
        <!-- [m] -->
        <!-- <mesh filename="package://rotors_description/meshes/propeller_${direction}.dae" -->
        <mesh filename="package://acl_sim/meshes/wilSelby/propeller_ccw.dae" scale=".12 .12 .12"/>
        <!-- <box size="${2*radius_rotor} 0.01 0.005"/> -->
      </geometry>
    </visual>
    <collision>
      <geometry>
        <cylinder length="0.005" radius="0.14"/>
        <!-- [m] -->
      </geometry>
    </collision>
  </link>
  <gazebo>
    <plugin filename="librotors_gazebo_motor_model.so" name="back_motor_model">
      <robotNamespace>quad</robotNamespace>
      <jointName>rotor_2_joint</jointName>
      <linkName>rotor_2</linkName>
      <turningDirection>ccw</turningDirection>
      <timeConstantUp>0.15</timeConstantUp>
      <timeConstantDown>0.15</timeConstantDown>
      <maxRotVelocity>770</maxRotVelocity>
      <motorConstant>2.39e-05</motorConstant>
      <momentConstant>0.016</momentConstant>
      <commandSubTopic>gazebo/command/motor_speed</commandSubTopic>
      <motorNumber>2</motorNumber>
      <rotorDragCoefficient>1.3858e-06</rotorDragCoefficient>
      <rollingMomentCoefficient>1e-06</rollingMomentCoefficient>
      <motorSpeedPubTopic>motor_speed/2</motorSpeedPubTopic>
      <rotorVelocitySlowdownSim>10</rotorVelocitySlowdownSim>
    </plugin>
  </gazebo>
  <gazebo reference="rotor_2">
    <material>Gazebo/Grey</material>
  </gazebo>
  <joint name="rotor_3_joint" type="continuous">
    <origin rpy="0 0 0" xyz="0 0.17 0.01"/>
    <axis xyz="0 0 1"/>
    <!-- TODO(ff): not currently set because it's not yet supported -->
    <!-- <limit effort="2000" velocity="${max_rot_velocity}" /> -->
    <parent link="base_link"/>
    <child link="rotor_3"/>
  </joint>
  <!-- TODO(ff): not currently set because it's not yet supported -->
  <!-- <gazebo reference="rotor_${motor_number}_joint"> <axis> <xyz>0 0 1</xyz>
      <limit> <velocity> ${max_rot_velocity} </velocity> </limit> </axis> </gazebo> -->
  <link name="rotor_3">
    <inertial>
      <mass value="0.005"/>
      <!-- [kg] -->
      <inertia ixx="9.75e-07" ixy="0.0" ixz="0.0" iyy="0.00032670416666666667" iyz="0.0" izz="0.0003276041666666667"/>
    </inertial>
    <visual>
      <geometry>
        <!-- <cylinder length="0.005" radius="${radius_rotor}"/> -->
        <!-- [m] -->
        <!-- <mesh filename="package://rotors_description/meshes/propeller_${direction}.dae" -->
        <mesh filename="package://acl_sim/meshes/wilSelby/propeller_cw.dae" scale=".12 .12 .12"/>
        <!-- <box size="${2*radius_rotor} 0.01 0.005"/> -->
      </geometry>
    </visual>
    <collision>
      <geometry>
        <cylinder length="0.005" radius="0.14"/>
        <!-- [m] -->
      </geometry>
    </collision>
  </link>
  <gazebo>
    <plugin filename="librotors_gazebo_motor_model.so" name="left_motor_model">
      <robotNamespace>quad</robotNamespace>
      <jointName>rotor_3_joint</jointName>
      <linkName>rotor_3</linkName>
      <turningDirection>cw</turningDirection>
      <timeConstantUp>0.15</timeConstantUp>
      <timeConstantDown>0.15</timeConstantDown>
      <maxRotVelocity>770</maxRotVelocity>
      <motorConstant>2.39e-05</motorConstant>
      <momentConstant>0.016</momentConstant>
      <commandSubTopic>gazebo/command/motor_speed</commandSubTopic>
      <motorNumber>3</motorNumber>
      <rotorDragCoefficient>1.3858e-06</rotorDragCoefficient>
      <rollingMomentCoefficient>1e-06</rollingMomentCoefficient>
      <motorSpeedPubTopic>motor_speed/3</motorSpeedPubTopic>
      <rotorVelocitySlowdownSim>10</rotorVelocitySlowdownSim>
    </plugin>
  </gazebo>
  <gazebo reference="rotor_3">
    <material>Gazebo/Grey</material>
  </gazebo>
  <gazebo>
    <plugin filename="librotors_gazebo_controller_interface.so" name="controller_interface">
      <robotNamespace>quad</robotNamespace>
      <commandAttitudeThrustSubTopic>command/attitude</commandAttitudeThrustSubTopic>
      <commandRateThrustSubTopic>command/rate</commandRateThrustSubTopic>
      <commandMotorSpeedSubTopic>command/motor_speed</commandMotorSpeedSubTopic>
      <imuSubTopic>imu</imuSubTopic>
      <motorSpeedCommandPubTopic>gazebo/command/motor_speed</motorSpeedCommandPubTopic>
    </plugin>
  </gazebo>
  <!-- IMU link -->
  <link name="quad/imu_link">
    <inertial>
      <inertia ixx="0.00001" ixy="0.0" ixz="0.0" iyy="0.00001" iyz="0.0" izz="0.00001"/>
      <mass value="0.015"/>
      <!-- [kg] -->
      <origin rpy="0 0 0" xyz="0 0 0"/>
    </inertial>
  </link>
  <!-- IMU joint -->
  <joint name="quad/imu_joint" type="revolute">
    <origin rpy="0 0 0" xyz="0 0 0"/>
    <parent link="base_link"/>
    <child link="quad/imu_link"/>
    <limit effort="0" lower="0" upper="0" velocity="0"/>
  </joint>
  <gazebo>
    <plugin filename="librotors_gazebo_imu_plugin.so" name="rotors_gazebo_imu_plugin">
      <!-- A good description of the IMU parameters can be found in the kalibr documentation:
           https://github.com/ethz-asl/kalibr/wiki/IMU-Noise-Model-and-Intrinsics -->
      <robotNamespace>quad</robotNamespace>
      <!-- (string, required): ros namespace in which the messages are published -->
      <linkName>quad/imu_link</linkName>
      <!-- (string, required): name of the body which holds the IMU sensor -->
      <imuTopic>imu</imuTopic>
      <!-- (string): name of the sensor output topic and prefix of service names (defaults to imu) -->
      <gyroscopeNoiseDensity>0.0003394</gyroscopeNoiseDensity>
      <!-- Gyroscope noise density (two-sided spectrum) [rad/s/sqrt(Hz)] -->
      <gyroscopeRandomWalk>3.8785e-05</gyroscopeRandomWalk>
      <!-- Gyroscope bias random walk [rad/s/s/sqrt(Hz)] -->
      <gyroscopeBiasCorrelationTime>1000.0</gyroscopeBiasCorrelationTime>
      <!-- Gyroscope bias correlation time constant [s] -->
      <gyroscopeTurnOnBiasSigma>0.0087</gyroscopeTurnOnBiasSigma>
      <!-- Gyroscope turn on bias standard deviation [rad/s] -->
      <accelerometerNoiseDensity>0.004</accelerometerNoiseDensity>
      <!-- Accelerometer noise density (two-sided spectrum) [m/s^2/sqrt(Hz)] -->
      <accelerometerRandomWalk>0.006</accelerometerRandomWalk>
      <!-- Accelerometer bias random walk. [m/s^2/s/sqrt(Hz)] -->
      <accelerometerBiasCorrelationTime>300.0</accelerometerBiasCorrelationTime>
      <!-- Accelerometer bias correlation time constant [s] -->
      <accelerometerTurnOnBiasSigma>0.196</accelerometerTurnOnBiasSigma>
      <!-- Accelerometer turn on bias standard deviation [m/s^2] -->
    </plugin>
  </gazebo>
  <link name="quad/camera__link">
    <visual>
      <origin rpy="0 0 0" xyz="0 0 0"/>
      <geometry>
        <mesh filename="package://acl_sim/meshes/wilSelby/kinect_camera_simple.dae"/>
      </geometry>
    </visual>
    <collision>
      <origin rpy="0 0 0" xyz="0 0 0"/>
      <geometry>
        <cylinder length="0.01" radius="0.007"/>
        <mesh filename="package://acl_sim/meshes/wilSelby/kinect_camera_simple.stl"/>
      </geometry>
    </collision>
    <inertial>
      <mass value="1e-5"/>
      <origin rpy="0 0 0" xyz="0 0 0"/>
      <inertia ixx="1e-6" ixy="0" ixz="0" iyy="1e-6" iyz="0" izz="1e-6"/>
    </inertial>
  </link>
  <joint name="quad/camera__joint" type="fixed">
    <origin rpy="0 0 0" xyz="0.2 0.0 -0.04"/>
    <parent link="base_link"/>
    <child link="quad/camera__link"/>
    <limit effort="0" lower="0" upper="0" velocity="0"/>
  </joint>
  <!-- Optical center of camera -->
  <link name="quad/camera__optical_center_link"/>
  <joint name="quad/camera__optical_center_joint" type="fixed">
    <origin rpy="-1.5707963267948966 0 -1.5707963267948966" xyz="0 0 0"/>
    <parent link="quad/camera__link"/>
    <child link="quad/camera__optical_center_link"/>
    <limit effort="0" lower="0" upper="0" velocity="0"/>
  </joint>
  <gazebo reference="quad/camera__link">
    <sensor name="quad_camera_{camera_suffix}" type="depth">
      <always_on>true</always_on>
      <update_rate>30</update_rate>
      <camera>
        <horizontal_fov>2</horizontal_fov>
        <image>
          <format>R8G8B8</format>
          <width>640</width>
          <height>480</height>
        </image>
        <clip>
          <near>0.01</near>
          <far>100</far>
        </clip>
      </camera>
      <plugin filename="libgazebo_ros_openni_kinect.so" name="quad_camera_{camera_suffix}">
        <robotNamespace>quad</robotNamespace>
        <alwaysOn>true</alwaysOn>
        <baseline>0.11</baseline>
        <updateRate>30</updateRate>
        <cameraName>camera_</cameraName>
        <imageTopicName>camera/image_raw</imageTopicName>
        <cameraInfoTopicName>camera/camera_info</cameraInfoTopicName>
        <depthImageTopicName>depth/disparity</depthImageTopicName>
        <depthImageCameraInfoTopicName>depth/camera_info</depthImageCameraInfoTopicName>
        <pointCloudTopicName>depth/points</pointCloudTopicName>
        <frameName>camera__optical_center_link</frameName>
        <pointCloudCutoff>0.5</pointCloudCutoff>
        <distortionK1>0.0</distortionK1>
        <distortionK2>0.0</distortionK2>
        <distortionK3>0.0</distortionK3>
        <distortionT1>0.0</distortionT1>
        <distortionT2>0.0</distortionT2>
      </plugin>
    </sensor>
  </gazebo>
  <!-- IMU link -->
  <link name="quad/imugt_link">
    <inertial>
      <inertia ixx="0.00001" ixy="0.0" ixz="0.0" iyy="0.00001" iyz="0.0" izz="0.00001"/>
      <mass value="1e-05"/>
      <!-- [kg] -->
      <origin rpy="0 0 0" xyz="0 0 0"/>
    </inertial>
  </link>
  <!-- IMU joint -->
  <joint name="quad/imugt_joint" type="revolute">
    <origin rpy="0 0 0" xyz="0 0 0"/>
    <parent link="base_link"/>
    <child link="quad/imugt_link"/>
    <limit effort="0" lower="0" upper="0" velocity="0"/>
  </joint>
  <gazebo>
    <plugin filename="librotors_gazebo_imu_plugin.so" name="rotors_gazebo_imugt_plugin">
      <!-- A good description of the IMU parameters can be found in the kalibr documentation:
           https://github.com/ethz-asl/kalibr/wiki/IMU-Noise-Model-and-Intrinsics -->
      <robotNamespace>quad</robotNamespace>
      <!-- (string, required): ros namespace in which the messages are published -->
      <linkName>quad/imugt_link</linkName>
      <!-- (string, required): name of the body which holds the IMU sensor -->
      <imuTopic>ground_truth/imu</imuTopic>
      <!-- (string): name of the sensor output topic and prefix of service names (defaults to imu) -->
      <gyroscopeNoiseDensity>0.0</gyroscopeNoiseDensity>
      <!-- Gyroscope noise density (two-sided spectrum) [rad/s/sqrt(Hz)] -->
      <gyroscopeRandomWalk>0.0</gyroscopeRandomWalk>
      <!-- Gyroscope bias random walk [rad/s/s/sqrt(Hz)] -->
      <gyroscopeBiasCorrelationTime>1000.0</gyroscopeBiasCorrelationTime>
      <!-- Gyroscope bias correlation time constant [s] -->
      <gyroscopeTurnOnBiasSigma>0.0</gyroscopeTurnOnBiasSigma>
      <!-- Gyroscope turn on bias standard deviation [rad/s] -->
      <accelerometerNoiseDensity>0.0</accelerometerNoiseDensity>
      <!-- Accelerometer noise density (two-sided spectrum) [m/s^2/sqrt(Hz)] -->
      <accelerometerRandomWalk>0.0</accelerometerRandomWalk>
      <!-- Accelerometer bias random walk. [m/s^2/s/sqrt(Hz)] -->
      <accelerometerBiasCorrelationTime>300.0</accelerometerBiasCorrelationTime>
      <!-- Accelerometer bias correlation time constant [s] -->
      <accelerometerTurnOnBiasSigma>0.0</accelerometerTurnOnBiasSigma>
      <!-- Accelerometer turn on bias standard deviation [m/s^2] -->
    </plugin>
  </gazebo>
  <!-- odometry link -->
  <link name="quad/ground_truth/odometry_sensorgt_link">
    <inertial>
      <inertia ixx="0.00001" ixy="0.0" ixz="0.0" iyy="0.00001" iyz="0.0" izz="0.00001"/>
      <mass value="1e-05"/>
      <!-- [kg] -->
    </inertial>
  </link>
  <!-- odometry joint -->
  <joint name="quad/ground_truth/odometry_sensorgt_joint" type="revolute">
    <parent link="base_link"/>
    <origin rpy="0.0 0.0 0.0" xyz="0.0 0.0 0.0"/>
    <child link="quad/ground_truth/odometry_sensorgt_link"/>
    <limit effort="0" lower="0" upper="0" velocity="0"/>
  </joint>
  <gazebo>
    <plugin filename="librotors_gazebo_odometry_plugin.so" name="odometry_sensorgt">
      <linkName>base_link</linkName>
      <!--{namespace}/odometry_sensor${odometry_sensor_suffix}_link"-->
      <robotNamespace>quad/ground_truth</robotNamespace>
      <poseTopic>pose</poseTopic>
      <poseWithCovarianceTopic>pose_with_covariance</poseWithCovarianceTopic>
      <positionTopic>position</positionTopic>
      <transformTopic>transform</transformTopic>
      <odometryTopic>odometry</odometryTopic>
      <parentFrameId>world</parentFrameId>
      <!-- Use the scoped link name here. e.g. Model::link. -->
      <measurementDivisor>1</measurementDivisor>
      <!-- only every (seq % measurementDivisor) == 0 measurement is published [int] -->
      <measurementDelay>0</measurementDelay>
      <!-- time that measurement gets held back before it's published in [simulation cycles (int)] -->
      <unknownDelay>0.0</unknownDelay>
      <!-- additional delay, that just gets added to the timestamp [s] -->
      <noiseNormalPosition>0 0 0</noiseNormalPosition>
      <!-- standard deviation of additive white gaussian noise [m] -->
      <noiseNormalQuaternion>0 0 0</noiseNormalQuaternion>
      <!-- standard deviation white gaussian noise [rad]: q_m = q*quaternionFromSmallAngleApproximation(noiseNormalQ) -->
      <noiseNormalLinearVelocity>0 0 0</noiseNormalLinearVelocity>
      <!-- standard deviation of additive white gaussian noise [m/s] -->
      <noiseNormalAngularVelocity>0 0 0</noiseNormalAngularVelocity>
      <!-- standard deviation of additive white gaussian noise [rad/s] -->
      <noiseUniformPosition>0 0 0</noiseUniformPosition>
      <!-- symmetric bounds of uniform noise [m] -->
      <noiseUniformQuaternion>0 0 0</noiseUniformQuaternion>
      <!-- symmetric bounds of uniform noise [rad], computation see above -->
      <noiseUniformLinearVelocity>0 0 0</noiseUniformLinearVelocity>
      <!-- symmetric bounds of uniform noise [m/s] -->
      <noiseUniformAngularVelocity>0 0 0</noiseUniformAngularVelocity>
    </plugin>
  </gazebo>
</robot>

